/**
 * Integration Tests: Error Handling
 * Tests error handling across the application
 */

import React from 'react'
import { describe, it, expect, vi, beforeEach } from 'vitest'
import { render, screen, waitFor } from '@testing-library/react'
import userEvent from '@testing-library/user-event'
import { ErrorBoundary } from '@/components/shared/ErrorBoundary'
import { useApiErrorHandler } from '@/hooks/useApiErrorHandler'
import { NextIntlClientProvider } from 'next-intl'

// Mock next/navigation
const mockPush = vi.fn()
const mockRefresh = vi.fn()

vi.mock('next/navigation', () => ({
  useRouter: () => ({
    push: mockPush,
    refresh: mockRefresh,
  }),
  usePathname: () => '/dashboard',
}))

const messages = {
  errors: {
    title: 'Something went wrong',
    description: 'An unexpected error occurred',
    retry: 'Try Again',
    goHome: 'Go to Dashboard',
    unauthorized: 'Unauthorized',
    forbidden: 'Access Denied',
    notFound: 'Not Found',
    serverError: 'Server Error',
    networkError: 'Network Error',
  },
}

const TestWrapper = ({ children }: any) => (
  <NextIntlClientProvider locale="en" messages={messages}>
    {children}
  </NextIntlClientProvider>
)

// Component that throws an error
const ThrowError = ({ shouldThrow }: { shouldThrow: boolean }) => {
  if (shouldThrow) {
    throw new Error('Test error')
  }
  return <div>No error</div>
}

// Component that uses API error handler
const ApiErrorComponent = () => {
  const { handleError } = useApiErrorHandler()

  const triggerError = (status: number) => {
    const error: any = new Error('API Error')
    error.response = { status }
    handleError(error)
  }

  return (
    <div>
      <button onClick={() => triggerError(401)}>Trigger 401</button>
      <button onClick={() => triggerError(403)}>Trigger 403</button>
      <button onClick={() => triggerError(404)}>Trigger 404</button>
      <button onClick={() => triggerError(500)}>Trigger 500</button>
    </div>
  )
}

describe('Error Handling Integration Tests', () => {
  beforeEach(() => {
    vi.clearAllMocks()
    // Suppress console.error for expected errors
    vi.spyOn(console, 'error').mockImplementation(() => {})
  })

  describe('ErrorBoundary', () => {
    it('should catch and display errors', () => {
      render(
        <TestWrapper>
          <ErrorBoundary>
            <ThrowError shouldThrow={true} />
          </ErrorBoundary>
        </TestWrapper>
      )

      expect(screen.getByText(/something went wrong/i)).toBeInTheDocument()
    })

    it('should render children when no error', () => {
      render(
        <TestWrapper>
          <ErrorBoundary>
            <ThrowError shouldThrow={false} />
          </ErrorBoundary>
        </TestWrapper>
      )

      expect(screen.getByText('No error')).toBeInTheDocument()
    })

    it('should allow retry after error', async () => {
      const user = userEvent.setup()
      let shouldThrow = true

      const { rerender } = render(
        <TestWrapper>
          <ErrorBoundary>
            <ThrowError shouldThrow={shouldThrow} />
          </ErrorBoundary>
        </TestWrapper>
      )

      expect(screen.getByText(/something went wrong/i)).toBeInTheDocument()

      // Simulate fixing the error
      shouldThrow = false

      // Note: ErrorBoundary retry would need to be implemented with a reset mechanism
      // This is a simplified test
    })
  })

  describe('API Error Handling', () => {
    it('should handle 401 unauthorized errors', async () => {
      const user = userEvent.setup()

      render(
        <TestWrapper>
          <ApiErrorComponent />
        </TestWrapper>
      )

      const button = screen.getByText('Trigger 401')
      await user.click(button)

      await waitFor(() => {
        expect(mockPush).toHaveBeenCalledWith(expect.stringContaining('/login'))
      })
    })

    it('should handle 403 forbidden errors', async () => {
      const user = userEvent.setup()

      render(
        <TestWrapper>
          <ApiErrorComponent />
        </TestWrapper>
      )

      const button = screen.getByText('Trigger 403')
      await user.click(button)

      await waitFor(() => {
        expect(mockPush).toHaveBeenCalledWith(expect.stringContaining('/access-denied'))
      })
    })

    it('should handle 404 not found errors', async () => {
      const user = userEvent.setup()

      render(
        <TestWrapper>
          <ApiErrorComponent />
        </TestWrapper>
      )

      const button = screen.getByText('Trigger 404')
      await user.click(button)

      // 404 errors typically show a toast, not a redirect
      // This would need toast mocking to fully test
    })

    it('should handle 500 server errors', async () => {
      const user = userEvent.setup()

      render(
        <TestWrapper>
          <ApiErrorComponent />
        </TestWrapper>
      )

      const button = screen.getByText('Trigger 500')
      await user.click(button)

      // 500 errors typically show an error page or toast
      // This would need proper error state management to fully test
    })
  })

  describe('Network Error Handling', () => {
    it('should handle network failures gracefully', async () => {
      const { handleError } = useApiErrorHandler()

      // Simulate network error
      const networkError: any = new Error('Network Error')
      networkError.message = 'Network Error'

      // This would trigger offline indicator or retry logic
      expect(() => handleError(networkError)).not.toThrow()
    })
  })

  describe('Form Validation Errors', () => {
    it('should display validation errors with animations', async () => {
      // This would test form validation error display
      // Requires a form component with validation
      expect(true).toBe(true) // Placeholder
    })
  })
})
